{
  "call_id": "83d4871b-ec16-45b5-8d02-e4649553a02b",
  "error_message": "Attempt 4: HTTPSConnectionPool(host='app.customgpt.ai', port=443): Max retries exceeded with url: /api/v1/projects/50730/conversations/94632a51-1ffb-45a3-8b94-d3d61bef0df9/messages (Caused by NameResolutionError(\"<urllib3.connection.HTTPSConnection object at 0x7fab441c6290>: Failed to resolve 'app.customgpt.ai' ([Errno -3] Temporary failure in name resolution)\"))",
  "timestamp": "2025-09-18T23:12:41.656742+00:00",
  "sampler_name": "CustomGPT_RAG",
  "question_id": "6bbff75b"
}