{
  "call_id": "5a5f96d1-ecb8-4976-b760-261b30ab6459",
  "error_message": "Attempt 4: HTTPSConnectionPool(host='app.customgpt.ai', port=443): Max retries exceeded with url: /api/v1/projects/50730/conversations/94632a51-1ffb-45a3-8b94-d3d61bef0df9/messages (Caused by NameResolutionError(\"<urllib3.connection.HTTPSConnection object at 0x7fab43e15c10>: Failed to resolve 'app.customgpt.ai' ([Errno -3] Temporary failure in name resolution)\"))",
  "timestamp": "2025-09-18T23:26:56.456713+00:00",
  "sampler_name": "CustomGPT_RAG",
  "question_id": "7e067d6c"
}